<?xml version='1.0'?>
<robot name="erl1" xmlns:xacro="http://www.ros.org/wiki/xacro">

<xacro:include filename="$(find erl1)/urdf/erl1.gazebo" />

  <material name="blue">
    <color rgba="0.203125 0.23828125 0.28515625 1.0"/>
  </material>

  <link name="link_chassis">
  
    <!-- pose and inertial -->
    <pose>0 0 0.1 0 0 0</pose>
    
    <inertial>
      <mass value="5"/>
      <origin rpy="0 0 0" xyz="0 0 0.1"/>
      <inertia ixx="0.0395416666667" ixy="0" ixz="0" 
               iyy="0.106208333333" iyz="0" izz="0.106208333333"/>
    </inertial>

    <!-- body -->
    <collision name="collision_chassis">
      <geometry>
        <box size="0.5 0.3 0.07"/>
      </geometry>
    </collision>

    <visual>
      <origin rpy="0 0 0" xyz="0 0 0"/>
      <geometry>
        <box size="0.5 0.3 0.07"/>
      </geometry>
      <material name="blue"/>
    </visual>

    <!-- caster front -->
    <collision name="caster_front_collision">
      <origin rpy=" 0 0 0" xyz="0.35 0 -0.05"/>
      <geometry>
        <sphere radius="0.05"/>
      </geometry>
    </collision>

    <visual name="caster_front_visual">
      <origin rpy=" 0 0 0" xyz="0.2 0 -0.05"/>
      <geometry>
        <sphere radius="0.05"/>
      </geometry>
    </visual>
  </link>

<!-- left wheel -->
 <link name='left_wheel'>
    <inertial>
      <mass value="5.0"/>
      <origin xyz="0 0 0" rpy="0 1.5707 1.5707"/>
      <inertia
          ixx="0.014" ixy="0" ixz="0"
          iyy="0.014" iyz="0"
          izz="0.025"
      />
    </inertial>

    <collision>
      <origin xyz="0 0 0" rpy="0 1.5707 1.5707"/> 
      <geometry>
        <cylinder radius=".1" length=".05"/>
      </geometry>
    </collision>

    <visual name='left_wheel_visual'>
      <origin xyz="0 0 0" rpy="0 1.5707 1.5707"/>
      <geometry>
        <cylinder radius=".1" length=".05"/>
      </geometry>
    </visual>
  </link>

<!-- right wheel -->
<link name='right_wheel'>
    <inertial>
      <mass value="5.0"/>
      <origin xyz="0 0 0" rpy="0 1.5707 1.5707"/>
      <inertia
          ixx="0.014" ixy="0" ixz="0"
          iyy="0.014" iyz="0"
          izz="0.025"
      />
    </inertial>

    <collision>
      <origin xyz="0 0 0" rpy="0 1.5707 1.5707"/> 
      <geometry>
        <cylinder radius=".1" length=".05"/>
      </geometry>
    </collision>

    <visual name='right_wheel_visual'>
      <origin xyz="0 0 0" rpy="0 1.5707 1.5707"/>
      <geometry>
        <cylinder radius=".1" length=".05"/>
      </geometry>
    </visual>
</link>

<!-- joint types-->
<joint type="continuous" name="right_wheel_joint">
    <origin xyz="-0.1 -0.15 0" rpy="0 0 0"/>
    <child link="right_wheel"/>
    <parent link="link_chassis"/>
    <axis xyz="0 1 0" rpy="0 0 0"/>
    <limit effort="100" velocity="10"/>
    <dynamics damping="1.0" friction="1.0"/>
  </joint>  
  
<joint type="continuous" name="left_wheel_joint">
    <origin xyz="-0.1 0.15 0" rpy="0 0 0"/>
    <child link="left_wheel"/>
    <parent link="link_chassis"/>
    <axis xyz="0 1 0" rpy="0 0 0"/>
    <limit effort="100" velocity="10"/>
    <dynamics damping="1.0" friction="1.0"/>
  </joint>

<!-- ex1 -->
<link name="link_cube">
  <visual name="visual_cube">
    <origin xyz="0 0 0.05" rpy="0 0 0"/>
    <geometry>
      <box size="0.1 0.1 0.1"/>
    </geometry>
    <material name="blue"/>
  </visual>
  <collision>
    <origin xyz="0 0 0" rpy="0 0 0"/>
    <geometry>
      <box size="0.1 0.1 0.1"/>
    </geometry>
  </collision>
  <inertial>
    <mass value="0.3"/>
    <origin xyz="0 0 0" rpy="0 0 0"/>
    <inertia
      ixx="0.000125" ixy="0" ixz="0"
      iyy="0.0010625" iyz="0" izz="0.0010625"/>
  </inertial>
</link>

<joint name="cube_joint" type="revolute">
  <parent link="link_chassis"/>
  <child link="link_cube"/>
  <origin xyz="0 0 0.035" rpy="0 0 0"/>
  <axis xyz="0 0 1"/>
  <limit lower="-1.57" upper="1.57" effort="5" velocity="1.0"/>
</joint>

<link name="link_arm">
  <visual>
    <origin xyz="0.5 0 0" rpy="0 0 0"/>
    <geometry>
      <box size="1.0 0.05 0.05"/>
    </geometry>
    <material name="blue"/>
  </visual>
  <collision>
    <geometry>
      <box size="1.0 0.05 0.05"/>
    </geometry>
  </collision>
  <inertial>
    <mass value="1.0"/>
    <origin xyz="0 0 0" rpy="0 0 0"/>
    <inertia
      ixx="0.0004167" ixy="0" ixz="0"
      iyy="0.0835417" iyz="0" izz="0.0835417"/>
  </inertial>
</link>

<joint name="arm_joint" type="revolute">
  <parent link="link_cube"/>
  <child link="link_arm"/>
  <origin xyz="0 0 0.1" rpy="0 0 0"/>
  <axis xyz="0 1 0"/>
  <limit lower="-3.0" upper="-0.1" effort="5" velocity="1.0"/>
</joint>

</robot>