<?xml version='1.0'?>
<robot name="erl1" xmlns:xacro="http://www.ros.org/wiki/xacro">

  <xacro:include filename="$(find erl1)/urdf/erl1.gazebo" />

  <material name="blue">
    <color rgba="0.203125 0.23828125 0.28515625 1.0"/>
  </material>

  <link name="link_chassis">
  
    <pose>0 0 0.1 0 0 0</pose>
    
    <inertial>
      <mass value="5"/>
      <origin rpy="0 0 0" xyz="0 0 0.1"/>
      <inertia 
        ixx="0.0395416666667" ixy="0" ixz="0" 
        iyy="0.106208333333" iyz="0" izz="0.106208333333"/>
    </inertial>

    <collision name="collision_chassis">
      <geometry>
        <mesh filename="package://erl1/meshes/mogi_bot.dae"/>
      </geometry>
    </collision>

    <visual>
      <origin rpy="0 0 0" xyz="0 0 0"/>
      <geometry>
        <mesh filename="package://erl1/meshes/mogi_bot.dae"/>
      </geometry>
      <material name="blue"/>
    </visual>

    <collision name="caster_front_collision">
      <origin rpy="0 0 0" xyz="0.35 0 -0.05"/>
      <geometry>
        <sphere radius="0.05"/>
      </geometry>
    </collision>

    <visual name="caster_front_visual">
      <origin rpy="0 0 0" xyz="0.2 0 -0.05"/>
      <geometry>
        <sphere radius="0.05"/>
      </geometry>
    </visual>
  </link>

  <link name='left_wheel'>
    <inertial>
      <mass value="5.0"/>
      <origin xyz="0 0 0" rpy="0 1.5707 1.5707"/>
      <inertia
        ixx="0.014" ixy="0" ixz="0"
        iyy="0.014" iyz="0"
        izz="0.025"/>
    </inertial>

    <collision>
      <origin xyz="0 0 0" rpy="0 1.5707 1.5707"/> 
      <geometry>
        <cylinder radius=".1" length=".05"/>
      </geometry>
    </collision>

    <visual name='left_wheel_visual'>
      <origin xyz="0 0 0" rpy="0 1.5707 1.5707"/>
      <geometry>
        <cylinder radius=".1" length=".05"/>
      </geometry>
    </visual>
  </link>

  <link name='right_wheel'>
    <inertial>
      <mass value="5.0"/>
      <origin xyz="0 0 0" rpy="0 1.5707 1.5707"/>
      <inertia
        ixx="0.014" ixy="0" ixz="0"
        iyy="0.014" iyz="0"
        izz="0.025"/>
    </inertial>

    <collision>
      <origin xyz="0 0 0" rpy="0 1.5707 1.5707"/> 
      <geometry>
        <cylinder radius=".1" length=".05"/>
      </geometry>
    </collision>

    <visual name='right_wheel_visual'>
      <origin xyz="0 0 0" rpy="0 1.5707 1.5707"/>
      <geometry>
        <cylinder radius=".1" length=".05"/>
      </geometry>
    </visual>
  </link>

  <joint type="continuous" name="right_wheel_joint">
    <origin xyz="-0.1 -0.15 0" rpy="0 0 0"/>
    <child link="right_wheel"/>
    <parent link="link_chassis"/>
    <axis xyz="0 1 0" rpy="0 0 0"/>
    <limit effort="100" velocity="10"/>
    <dynamics damping="1.0" friction="1.0"/>
  </joint>  
  
  <joint type="continuous" name="left_wheel_joint">
    <origin xyz="-0.1 0.15 0" rpy="0 0 0"/>
    <child link="left_wheel"/>
    <parent link="link_chassis"/>
    <axis xyz="0 1 0" rpy="0 0 0"/>
    <limit effort="100" velocity="10"/>
    <dynamics damping="1.0" friction="1.0"/>
  </joint>

  <gazebo reference="left_wheel">
    <mu1>0.5</mu1>
    <mu2>0.5</mu2>
    <kp>1000000.0</kp>
    <kd>100.0</kd>
    <minDepth>0.0001</minDepth>
    <maxVel>1.0</maxVel>
  </gazebo>

  <gazebo reference="right_wheel">
    <mu1>0.5</mu1>
    <mu2>0.5</mu2>
    <kp>1000000.0</kp>
    <kd>100.0</kd>
    <minDepth>0.0001</minDepth>
    <maxVel>1.0</maxVel>
  </gazebo>

  <gazebo reference="link_chassis">
    <mu1>0.000002</mu1>
    <mu2>0.000002</mu2>
  </gazebo>

  <!-- camera sensor -->
  <joint type="fixed" name="camera_joint">
    <origin xyz="0.225 0 0.075" rpy="0 0 0"/>
    <child link="camera_link"/>
    <parent link="base_link"/>
    <axis xyz="0 1 0"/>
  </joint>

  <link name="camera_link">
    <pose>0 0 0 0 0 0</pose>
    
    <inertial>
      <mass value="0.1"/>
      <origin xyz="0 0 0" rpy="0 0 0"/>
      <inertia
        ixx="1e-6" ixy="0" ixz="0" 
        iyy="1e-6" iyz="0" izz="1e-6"/>
    </inertial>

    <collision name="collision">
      <origin xyz="0 0 0" rpy="0 0 0"/>
      <geometry>
        <box size=".03 .03 .03"/>
      </geometry>
    </collision>
    
    <visual name="camera_link_visual">
      <origin xyz="0 0 0" rpy="0 0 0"/>
      <geometry>
        <box size=".03 .03 .03"/>
      </geometry>
    </visual>
  </link>

  <!-- camera optical joint -->
  <joint type="fixed" name="camera_optical_joint">
    <origin xyz="0 0 0" rpy="-1.5707 0 -1.5707"/>
    <child link="camera_link_optical"/>
    <parent link="camera_link"/>
  </joint>

  <link name="camera_link_optical">
  </link>

</robot>